Workbook

Sheet Ranking por valor de estoque
B1: Banner: Ranking de estoque por valor a custo (ajustado), com classificacao de giro por bucket de dias sem venda (aproximado por periodo fechado). Fonte: 4 periodos de Curva ABC (mai/2025 a jun/2026) + snapshot de estoque 03/08/2026. Outliers criticos (codigos 7153, 7874) excluidos. Gerado em 26/08/2026.
A2: Filtro | B2: codigo | C2: produto | D2: categoria | E2: fornecedor | F2: qtde | G2: custo_unit_usado | H2: valor_estoque_ajustado | I2: preco | J2: margem_cadastrada_pct | K2: bucket_giro | L2: dias_sem_venda_minimo | M2: ultimo_periodo_com_venda | N2: notas
A3: =_xlfn.XLOOKUP(C:C,'Resumo por bucket'!F:F,'Resumo por bucket'!I:I,"") -> 0 | B3: 1986 | C3: CUMEEIRA ZINCALUM 0.43 | D3: MATERIAL BASICO | F3: 2998 | G3: 26 | H3: 77948 | I3: 41 | J3: 57.69 | K3: Nunca vendeu (14 meses) | N3: Vendida por encomenda (confirmado Tony 26/08/2026). Giro zero e esperado, nao e estoque parado real.
A4: =_xlfn.XLOOKUP(C:C,'Resumo por bucket'!F:F,'Resumo por bucket'!I:I,"") | B4: 51 | C4: AREIA FINA | D4: MATERIAL BASICO | E4: CB MATERIAL DE CONSTRUCAO | F4: 1099.2681 | G4: 70.83 | H4: 77861.16 | I4: 130 | J4: 83.53 | K4: 31 a 60 dias | L4: 34 | M4: P4
A5: =_xlfn.XLOOKUP(C:C,'Resumo por bucket'!F:F,'Resumo por bucket'!I:I,"") -> 0 | B5: 3746 | C5: VARETA SOLDA OXI 1.59MM GERDAU | D5: MD-MD-MD-MD-MD- MD-MD-MD-MD-MD- | E5: COMERCIAL GERDAU | F5: 7329 | G5: 10.2 | H5: 74755.8 | I5: 25 | J5: 145.1 | K5: Nunca vendeu (14 meses) | N5: Slow-mover genuino (confirmado Tony 26/08/2026), nao erro de leitura.
A6: =_xlfn.XLOOKUP(C:C,'Resumo por bucket'!F:F,'Resumo por bucket'!I:I,"") | B6: 1322 | C6: AREIA MEDIA | D6: MATERIAL BASICO | E6: CB MATERIAL DE CONSTRUCAO | F6: 668.5256 | G6: 70.83 | H6: 47351.67 | I6: 130 | J6: 83.53 | K6: 31 a 60 dias | L6: 34 | M6: P4
A7: =_xlfn.XLOOKUP(C:C,'Resumo por bucket'!F:F,'Resumo por bucket'!I:I,"") | B7: 92 | C7: PEDRA BRITADA 1 (19) | D7: MATERIAL BASICO | E7: MILTON ALVES FERREIRA | F7: 190.9622 | G7: 100 | H7: 19096.22 | I7: 220 | J7: 120 | K7: 31 a 60 dias | L7: 34 | M7: P4
A8: =_xlfn.XLOOKUP(C:C,'Resumo por bucket'!F:F,'Resumo por bucket'!I:I,"") -> 0 | B8: 11024 | C8: SACOLA RECICLADAS VD 60X80 | D8: MATERIAL DE USO E CONSUMO | E8: VINICIUS DE SOUSA AMARO LTDA | F8: 1015 | G8: 11.5 | H8: 11672.5 | I8: 20 | J8: 73.91 | K8: Nunca vendeu (14 meses)
A9: =_xlfn.XLOOKUP(C:C,'Resumo por bucket'!F:F,'Resumo por bucket'!I:I,"") | B9: 98 | C9: PEDRA BRITADA 0 (CASCALHINHO) | D9: MATERIAL BASICO | E9: MILTON ALVES FERREIRA | F9: 105.1551 | G9: 106.67 | H9: 11216.89 | I9: 240 | J9: 125 | K9: 31 a 60 dias | L9: 34 | M9: P4
A10: =_xlfn.XLOOKUP(C:C,'Resumo por bucket'!F:F,'Resumo por bucket'!I:I,"") -> 0 | B10: 3214 | C10: TUBO PVC ROSCA 1 POL TIGRE | D10: MD-MD-MD-MD-MD- MD-MD-MD-MD-MD- | F10: 999.83 | G10: 8.06 | H10: 8058.63 | I10: 96 | J10: 1091.07 | K10: Nunca vendeu (14 meses) | N10: Produto de giro baixo confirmado (Tony 26/08/2026). Duvida de cadastro (custo/preco/qtde) segue em aberto, ver diagnostico giro-estoque anterior.
A11: =_xlfn.XLOOKUP(C:C,'Resumo por bucket'!F:F,'Resumo por bucket'!I:I,"") | B11: 7972 | C11: CIMENTO POTY CPII Z 32 TODAS AS OBRAS SC 50KG | D11: MATERIAL BASICO | E11: VCNE - FABRICA PAULISTA | F11: 174 | G11: 38.22 | H11: 6650.28 | I11: 51 | J11: 33.44 | K11: 31 a 60 dias | L11: 34 | M11: P4
A12: =_xlfn.XLOOKUP(C:C,'Resumo por bucket'!F:F,'Resumo por bucket'!I:I,"") | B12: 2791 | C12: TRELICA PREMOLDADA TG8 SL 6/3 X 4/4.2MM | D12: MATERIAL BASICO | E12: RJ FERRAGENS | F12: 595.3 | G12: 11 | H12: 6548.3 | I12: 22 | J12: 100 | K12: 31 a 60 dias | L12: 34 | M12: P4
A13: =_xlfn.XLOOKUP(C:C,'Resumo por bucket'!F:F,'Resumo por bucket'!I:I,"") | B13: 11225 | C13: SACO DE AREIA IMPRESSO 40x60 | D13: MATERIAL DE USO E CONSUMO | E13: I3S INDUSTRIA E COMERCIO DE MATERIAIS PLASTICOS E | F13: 8138 | G13: 0.68 | H13: 5533.84 | I13: 2 | J13: 196.3 | K13: 31 a 60 dias | L13: 34 | M13: P4
A14: =_xlfn.XLOOKUP(C:C,'Resumo por bucket'!F:F,'Resumo por bucket'!I:I,"") | B14: 1344 | C14: TELHA CANAL TIPO RUSSA 2a. | D14: COBERTURA | E14: CERAMICA CRISTO REY LTDA | F14: 5585.1 | G14: 0.93 | H14: 5194.14 | I14: 1.4 | J14: 50.54 | K14: 31 a 60 dias | L14: 34 | M14: P4
A15: =_xlfn.XLOOKUP(C:C,'Resumo por bucket'!F:F,'Resumo por bucket'!I:I,"") | B15: 87 | C15: PEDRA CALCARIA | D15: MATERIAL BASICO | E15: MARCOS ANTONIO DOS SANTOS BATISTA JUNIOR | F15: 73.175 | G15: 66.67 | H15: 4878.58 | I15: 250 | J15: 275 | K15: 31 a 60 dias | L15: 34 | M15: P4
A16: =_xlfn.XLOOKUP(C:C,'Resumo por bucket'!F:F,'Resumo por bucket'!I:I,"") | B16: 15847 | C16: SACOS RAFIA DE PP 50X63 LAM CONSTRUMAIS | D16: UTILIDADES E JARDIM | E16: CARUPLAST INDUSTRIA E COMERCIO LTDA | F16: 5334 | G16: 0.89 | H16: 4747.26 | I16: 2 | J16: 124.72 | K16: 31 a 60 dias | L16: 34 | M16: P4
A17: =_xlfn.XLOOKUP(C:C,'Resumo por bucket'!F:F,'Resumo por bucket'!I:I,"") | B17: 167 | C17: TELHA CANAL TIPO RUSSA 1a. | D17: COBERTURA | E17: CERAMICA CRISTO REY LTDA | F17: 4324 | G17: 0.96 | H17: 4151.04 | I17: 1.4 | J17: 45.83 | K17: 31 a 60 dias | L17: 34 | M17: P4
A18: =_xlfn.XLOOKUP(C:C,'Resumo por bucket'!F:F,'Resumo por bucket'!I:I,"") -> X | B18: 13801 | C18: TELA MOEDA FERRO 1.90CM ESP 580CM ALT 19.72 FURO PRENSAL | D18: MATERIAL BASICO | E18: PRENSAL INDUSTRIA METALURGICA LTDA | F18: 89.001 | G18: 44.33 | H18: 3945.41 | I18: 76 | J18: 71.45 | K18: Acima de 180 dias | L18: 276 | M18: P1
A19: =_xlfn.XLOOKUP(C:C,'Resumo por bucket'!F:F,'Resumo por bucket'!I:I,"") | B19: 147 | C19: COLUNA FERRO 5/16 8.00MM 07X17 | D19: MATERIAL BASICO | E19: ALUMIFER ALUMINIO E FERRO LTDA. | F19: 297.5 | G19: 12.34 | H19: 3671.15 | I19: 22 | J19: 78.35 | K19: 31 a 60 dias | L19: 34 | M19: P4
A20: =_xlfn.XLOOKUP(C:C,'Resumo por bucket'!F:F,'Resumo por bucket'!I:I,"") | B20: 11693 | C20: ABRACADEIRA NYLON BR 140X3.50 FOXLUX | D20: FERRAGEM | E20: ALMEIDA | F20: 59400.02 | G20: 0.06 | H20: 3564 | I20: 0.15 | J20: 150 | K20: 31 a 60 dias | L20: 34 | M20: P4
A21: =_xlfn.XLOOKUP(C:C,'Resumo por bucket'!F:F,'Resumo por bucket'!I:I,"") | B21: 148 | C21: COLUNA FERRO 3/8 10.00MM 07X17 | D21: MATERIAL BASICO | E21: ALUMIFER ALUMINIO E FERRO LTDA. | F21: 211 | G21: 16.79 | H21: 3542.69 | I21: 30 | J21: 78.73 | K21: 31 a 60 dias | L21: 34 | M21: P4
A22: =_xlfn.XLOOKUP(C:C,'Resumo por bucket'!F:F,'Resumo por bucket'!I:I,"") | B22: 15800 | C22: CERAMICA 46X46 BR.NEVE EXT 2.79M2 STELA | D22: CERAMICA | E22: PAMESA DO BRASIL S/A | F22: 225.99 | G22: 15.61 | H22: 3527.7 | I22: 32.9 | J22: 110.77 | K22: 31 a 60 dias | L22: 34 | M22: P4
A23: =_xlfn.XLOOKUP(C:C,'Resumo por bucket'!F:F,'Resumo por bucket'!I:I,"") | B23: 3822 | C23: PEDRA RACHINHA IRREGULAR | D23: MATERIAL BASICO | E23: SIDNEI PEREIRA RODRIGUES | F23: 162 | G23: 20 | H23: 3240 | I23: 30 | J23: 50 | K23: 31 a 60 dias | L23: 34 | M23: P4
A24: =_xlfn.XLOOKUP(C:C,'Resumo por bucket'!F:F,'Resumo por bucket'!I:I,"") -> 0 | B24: 14346 | C24: METALON GALV 30MM X 20MM 1.25MM - CH 18 | D24: MATERIAL BASICO | E24: ACO BRAZIL | F24: 47.2 | G24: 62.36 | H24: 2943.39 | I24: 95 | J24: 52.34 | K24: Nunca vendeu (14 meses)
A25: =_xlfn.XLOOKUP(C:C,'Resumo por bucket'!F:F,'Resumo por bucket'!I:I,"") -> 0 | B25: 8953 | C25: TORNEIRA MET FILTRO ABS BM 2172 C40 CR IMPERATRIZ METAIS | D25: MD-MD-MD-MD-MD- MD-MD-MD-MD-MD- | E25: MARTINS | F25: 27 | G25: 96.28 | H25: 2599.56 | I25: 160 | J25: 66.18 | K25: Nunca vendeu (14 meses)
A26: =_xlfn.XLOOKUP(C:C,'Resumo por bucket'!F:F,'Resumo por bucket'!I:I,"") | B26: 15996 | C26: TINTA EPOXI BA BICOMP P/SINALIZACAO CZ MEDIO BD 18L VIMASTER | D26: PINTURA | E26: VIMASTER INDUSTRIA E COMERCIO DE COMPONENTES DE VI | F26: 5 | G26: 513.84 | H26: 2569.2 | I26: 820 | J26: 59.58 | K26: 31 a 60 dias | L26: 34 | M26: P4
A27: =_xlfn.XLOOKUP(C:C,'Resumo por bucket'!F:F,'Resumo por bucket'!I:I,"") -> 0 | B27: 461 | C27: LINHA MISTA 3X6 BIT 5X13CM | D27: COBERTURA | E27: O ATACADAO DA MADEIRA | F27: 67.5011 | G27: 33.5 | H27: 2261.29 | I27: 52 | J27: 55.22 | K27: 121 a 150 dias | L27: 125 | M27: P3
A28: =_xlfn.XLOOKUP(C:C,'Resumo por bucket'!F:F,'Resumo por bucket'!I:I,"") -> 0 | B28: 15511 | C28: MADEIRITE PLASTIFICADO 1.10X2.20 18MM | D28: MATERIAL BASICO | E28: AMDS MADEIRAS E MATERIAIS DE CONSTRUCAO | F28: 10 | G28: 222 | H28: 2220 | I28: 340 | J28: 53.15 | K28: Acima de 180 dias | L28: 215 | M28: P2
A29: =_xlfn.XLOOKUP(C:C,'Resumo por bucket'!F:F,'Resumo por bucket'!I:I,"") | B29: 14355 | C29: CERAMICA MAR GRIGIO 45x45 CX 2M2 TIPO A RAVELLO | D29: CERAMICA | E29: CERAMICA CAPRI LTDA | F29: 94 | G29: 23.53 | H29: 2211.82 | I29: 35.9 | J29: 52.58 | K29: 31 a 60 dias | L29: 34 | M29: P4
A30: =_xlfn.XLOOKUP(C:C,'Resumo por bucket'!F:F,'Resumo por bucket'!I:I,"") -> 0 | B30: 16124 | C30: TELA ALAMBRADO PRACTICA FIO 2.400MM 5X15 ALT 1.57MT BELGO | D30: MATERIAL BASICO | F30: 50 | G30: 42.6 | H30: 2130 | I30: 80 | J30: 87.79 | K30: Nunca vendeu (14 meses)
A31: =_xlfn.XLOOKUP(C:C,'Resumo por bucket'!F:F,'Resumo por bucket'!I:I,"") | B31: 101 | C31: BLOCO P/LAJE 30X07X20 | D31: MATERIAL BASICO | E31: ANTONIO TEODOSIO NETO - ME | F31: 1384 | G31: 1.5 | H31: 2076 | I31: 2.5 | J31: 66.67 | K31: 31 a 60 dias | L31: 34 | M31: P4
A32: =_xlfn.XLOOKUP(C:C,'Resumo por bucket'!F:F,'Resumo por bucket'!I:I,"") | B32: 15801 | C32: CERAMICA 46X46 PIPA EXT 2.79M2 STELA | D32: CERAMICA | E32: PAMESA DO BRASIL S/A | F32: 119.97 | G32: 15.61 | H32: 1872.73 | I32: 32.9 | J32: 110.77 | K32: 31 a 60 dias | L32: 34 | M32: P4
A33: =_xlfn.XLOOKUP(C:C,'Resumo por bucket'!F:F,'Resumo por bucket'!I:I,"") | B33: 15802 | C33: CERAMICA 46X46 SUME BR EXT 2.79M2 STELA | D33: CERAMICA | E33: PAMESA DO BRASIL S/A | F33: 119.97 | G33: 15.61 | H33: 1872.73 | I33: 32.9 | J33: 110.77 | K33: 31 a 60 dias | L33: 34 | M33: P4
A34: =_xlfn.XLOOKUP(C:C,'Resumo por bucket'!F:F,'Resumo por bucket'!I:I,"") | B34: 115 | C34: CANALETA PREMOLDADA CINTA 09X10X33 | D34: MATERIAL BASICO | E34: RJ FERRAGENS | F34: 374 | G34: 5 | H34: 1870 | I34: 10 | J34: 100 | K34: 31 a 60 dias | L34: 34 | M34: P4
A35: =_xlfn.XLOOKUP(C:C,'Resumo por bucket'!F:F,'Resumo por bucket'!I:I,"") | B35: 14789 | C35: TELHA PVC INCOLOR ONDAFORT 2,44X1,1M FORTLEV | D35: COBERTURA | E35: FORTLEV BA | F35: 13 | G35: 140.68 | H35: 1828.84 | I35: 240 | J35: 70.6 | K35: 31 a 60 dias | L35: 34 | M35: P4
A36: =_xlfn.XLOOKUP(C:C,'Resumo por bucket'!F:F,'Resumo por bucket'!I:I,"") -> 0 | B36: 11161 | C36: BOB. TERMICA 80 X 40 MTS PERSONALIZADA | D36: MATERIAL DE USO E CONSUMO | E36: EUCLIDES JOAQUIM DE OLIVEIRA ME | F36: 630 | G36: 2.83 | H36: 1782.9 | I36: 2.85 | J36: 0.59 | K36: Nunca vendeu (14 meses)
A37: =_xlfn.XLOOKUP(C:C,'Resumo por bucket'!F:F,'Resumo por bucket'!I:I,"") | B37: 112 | C37: TINTA PO C/10KG CH-1 CAL MEGAO | D37: PINTURA | E37: EMPRESA NACIONAL DE MAT DE CONSTRU | F37: 72 | G37: 24.5 | H37: 1764 | I37: 36 | J37: 46.94 | K37: 31 a 60 dias | L37: 34 | M37: P4
A38: =_xlfn.XLOOKUP(C:C,'Resumo por bucket'!F:F,'Resumo por bucket'!I:I,"") -> 0 | B38: 2540 | C38: REBOCAL MULTIUSO CH1 SC C/20KG MIBRA | D38: IMPERMEABILIZANT ES | E38: MIBRA MINERIOS | F38: 71 | G38: 24.6 | H38: 1746.6 | I38: 40 | J38: 62.6 | K38: Acima de 180 dias | L38: 276 | M38: P1
A39: =_xlfn.XLOOKUP(C:C,'Resumo por bucket'!F:F,'Resumo por bucket'!I:I,"") | B39: 723 | C39: ARGAMASSA COLA FORTE AC-II 15KG POLIMASSA | D39: ARGAMASSAS E REJUNTE | E39: POLIMASSA ARGAMASSAS | F39: 100 | G39: 15.95 | H39: 1595 | I39: 24 | J39: 50.45 | K39: 31 a 60 dias | L39: 34 | M39: P4
A40: =_xlfn.XLOOKUP(C:C,'Resumo por bucket'!F:F,'Resumo por bucket'!I:I,"") -> 0 | B40: 15525 | C40: BACIA P/CAIXA ACOPL IZY CONFORTO BR DECA | D40: LOUCAS SANITARIA | E40: DEXCO S.A.. | F40: 3 | G40: 527.27 | H40: 1581.81 | I40: 770 | J40: 46.04 | K40: Nunca vendeu (14 meses)
...

Sheet Resumo por bucket
A1: Bucket de giro (dias sem venda, aproximado) | B1: SKUs | C1: Valor em estoque (R$) | D1: % do total | F1: Rótulos de Linha | G1: Qtde! | H1: Valor! | I1: Filtro
A2: Ate 30 dias | B2: 0 | C2: 0 | D2: 0 | F2: 31 a 60 dias | G2: 95395.743 | H2: 285984.75
A3: 31 a 60 dias | B3: 1888 | C3: 426567.77 | D3: 48.23 | F3: 121 a 150 dias | G3: 358.9166 | H3: 6059.72
A4: 61 a 90 dias | B4: 0 | C4: 0 | D4: 0 | F4: LINHA MISTA 3X6 BIT 5X13CM | G4: 67.5011 | H4: 2261.29
A5: 91 a 120 dias | B5: 0 | C5: 0 | D5: 0 | F5: TELHA PVC INCOLOR ONDAFORT 3,05X1,1M FORTLEV | G5: 5 | H5: 970.85
A6: 121 a 150 dias | B6: 536 | C6: 45164.61 | D6: 5.11 | F6: CABO FLEX PP 4X2.5MM MT MEGATRON | G6: 99.4155 | H6: 892.75
A7: 151 a 180 dias | B7: 0 | C7: 0 | D7: 0 | F7: BOTA COURO P/CONST BICO ACO 41 VULCAFLEX | G7: 12 | H7: 797.28
A8: Acima de 180 dias | B8: 619 | C8: 53846.38 | D8: 6.09 | F8: CABO FLEX 4.0MM AZ PC MEGATRON | G8: 170 | H8: 576.3
A9: Nunca vendeu (14 meses) | B9: 1733 | C9: 351523.17 | D9: 39.75 | F9: DIALINE ESM SINT BR NEVE 3.0L | G9: 5 | H9: 561.25
A10: Sem historico (SKU novo) | B10: 68 | C10: 7254.58 | D10: 0.82 | F10: Acima de 180 dias | G10: 440.401 | H10: 12743.03
A11: TOTAL | B11: 4844 | C11: 884356.51 | D11: 100 | F11: TELA MOEDA FERRO 1.90CM ESP 580CM ALT 19.72 FURO PRENSAL | G11: 89.001 | H11: 3945.41 | I11: X
F12: MADEIRITE PLASTIFICADO 1.10X2.20 18MM | G12: 10 | H12: 2220
F13: REBOCAL MULTIUSO CH1 SC C/20KG MIBRA | G13: 71 | H13: 1746.6
F14: TELHA TRANSLUCIDA LEITOSA 2.44X1.10 GRANPLAST | G14: 7 | H14: 764.05
F15: ESCADA ALUM 05 DEG MOR | G15: 5 | H15: 742.8
F16: REFLETOR LED 200W PT 6500K BIV AVANT | G16: 8 | H16: 734.96
F17: PORTA SANF PVC 2.10X0.70CM BR NOVA FORMA | G17: 9 | H17: 729.99
F18: FORRO PVC LISO 200X7X4MT NOVA FORMA | G18: 34.4 | H18: 670.11 | I18: X
F19: CALHA BEIRAL PVC C/3M CAL/CKBR ASTRA | G19: 7 | H19: 649.11
F20: CHUMBADOR PBA 1/2 X 4.1/4 12414C ANCORA | G20: 200 | H20: 540
F21: Nunca vendeu (14 meses) | G21: 58475.62 | H21: 219342.29
F22: CUMEEIRA ZINCALUM 0.43 | G22: 2998 | H22: 77948
F23: VARETA SOLDA OXI 1.59MM GERDAU | G23: 7329 | H23: 74755.8
F24: SACOLA RECICLADAS VD 60X80 | G24: 1015 | H24: 11672.5
F25: TUBO PVC ROSCA 1 POL TIGRE | G25: 999.83 | H25: 8058.63
F26: METALON GALV 30MM X 20MM 1.25MM - CH 18 | G26: 47.2 | H26: 2943.39
F27: TORNEIRA MET FILTRO ABS BM 2172 C40 CR IMPERATRIZ METAIS | G27: 27 | H27: 2599.56
F28: TELA ALAMBRADO PRACTICA FIO 2.400MM 5X15 ALT 1.57MT BELGO | G28: 50 | H28: 2130
F29: BOB. TERMICA 80 X 40 MTS PERSONALIZADA | G29: 630 | H29: 1782.9
F30: BACIA P/CAIXA ACOPL IZY CONFORTO BR DECA | G30: 3 | H30: 1581.81
F31: COLORANTE ICORES BA AZ INTENSO P0441 0.9L | G31: 6708.31 | H31: 1542.91
F32: PORCELANATO BALI POLIDO 61X61 CX 1.88M2 TIPO A CERCAMP | G32: 30.08 | H32: 1469.11 | I32: X
F33: KIT ACO CACAU 40 COZIMAX | G33: 4 | H33: 1370.04 | I33: X
F34: BONE PERSONALIZADO CONSTRUMAIS | G34: 50 | H34: 1250
F35: PAPEL REPORT PR.A4 500F GR75 | G35: 46 | H35: 1244.3
F36: SACOLA CAMISETA IMPRESSO/ALTA 70 x 90 x 0,03 | G36: 2000 | H36: 1140
F37: PORTA SEMI OCA MOGNO 2.10X0.60X30MM ALPHA | G37: 10 | H37: 999
F38: ICORES DELANIL FOSCO BASE P 16L | G38: 4 | H38: 982.36
F39: SACOLA CAMISETA IMPRESSO/ALTA 50 x 70 x 0,03 | G39: 3000 | H39: 960
F40: SACO RECICLADO IMPRESSO TRANSPARENTE 43X70 - KG | G40: 50 | H40: 900
...

Sheet Ativo imobilizado (excluido)
A1: Itens de ativo imobilizado da propria loja (nao sao mercadoria de revenda), excluidos do ranking comercial acima, mesmo criterio ja usado nos periodos de Curva ABC (13 itens de ativo imobilizado excluidos da analise comercial).
A2: codigo | B2: produto | C2: categoria | D2: qtde | E2: valor_custo | F2: bucket_giro
A3: 9928 | B3: NOTE LENOVO IDEAPAD S145 I5 8GB 1TB WIN 10 PRATA | C3: ATIVO IMOBILIZADO | D3: 1 | E3: 2499 | F3: 31 a 60 dias
A4: 14160 | B4: TRICICLO MARCA TUKA MOD TK1200W COR AZ ANO/MOD 24/24 | C4: ATIVO IMOBILIZADO | D4: 1 | E4: 26000.4 | F4: 31 a 60 dias

Sheet Outliers criticos (excluidos)
A1: Itens com quantidade/custo em forte desacordo com os pares da mesma linha, pendente de confirmacao do Tony. Excluidos do ranking e dos totais acima. Ver diagnostico-giro-estoque.md, secao 03-08-2026, para o detalhe completo do benchmark.
A2: codigo | B2: produto | C2: categoria
A3: 7153 | B3: CABO FLEX 2.5MM AZ PC COBRECOM | C3: MATERIAL ELETRICO
A4: 7874 | B4: MANGUEIRA CORRUGADA 20MM AM - KRONA | C4: HIDRAULICA
